Workbook

Sheet student sheet T2
C1: ENGLISH LANG. | G1: MATHEMATICS | K1: IGBO LANGUAGE | O1: BIOLOGY | S1: CHEMISTRY | W1: PHYSICS | AA1: CRS | AE1: LITERATURE | AI1: AGRIC SCIENCE | AM1: ECONOMICS | AQ1: GEOGRAPHY | AU1: ANIMAL HUS. | AY1: GOVERNMENT | BC1: CIVIC EDU. | BG1: COMP. SCIENCE | BK1: MARKETING | BS1: FRENCH
A2: REG. No. | B2: Name | C2: CAT | D2: CAT2 | E2: EXAM | F2: TOTAL | G2: CAT3 | H2: CAT24 | I2: EXAM5 | J2: TOTAL6 | K2: CAT7 | L2: CAT28 | M2: EXAM9 | N2: TOTAL10 | O2: CAT11 | P2: CAT212 | Q2: EXAM13 | R2: TOTAL14 | S2: CAT15 | T2: CAT216 | U2: EXAM17 | V2: TOTAL18 | W2: CAT19 | X2: CAT220 | Y2: EXAM21 | Z2: TOTAL22 | AA2: CAT23 | AB2: CAT224 | AC2: EXAM25 | AD2: TOTAL26 | AE2: CAT27 | AF2: CAT228 | AG2: EXAM29 | AH2: TOTAL30 | AI2: CAT31 | AJ2: CAT232 | AK2: EXAM33 | AL2: TOTAL34 | AM2: CAT35 | AN2: CAT236 | AO2: EXAM37 | AP2: TOTAL38 | AQ2: CAT39 | AR2: CAT240 | AS2: EXAM41 | AT2: TOTAL42 | AU2: CAT43 | AV2: CAT244 | AW2: EXAM45 | AX2: TOTAL46 | AY2: CAT47 | AZ2: CAT248 | BA2: EXAM49 | BB2: TOTAL50 | BC2: CAT51 | BD2: CAT252 | BE2: EXAM53 | BF2: TOTAL54 | BG2: CAT55 | BH2: CAT256 | BI2: EXAM57 | BJ2: TOTAL58 | BK2: CAT59 | BL2: CAT260 | BM2: EXAM61 | BN2: TOTAL62 | BO2: CA1 | BP2: CAT264 | BQ2: EXAM65 | BR2: TOTAL66 | BS2: CAT67 | BT2: CAT268 | BU2: EXAM69 | BV2: TOTAL70
A3: ='[1]student detail'!A2 -> BDS/22/001 | B3: ='[1]student detail'!B2 -> AMA LIGHT NNEOMA | C3: 10 | D3: 12 | E3: 52 | F3: =SUM(Table_6[[#This Row],[CAT]:[EXAM]]) -> 74 | J3: =SUM(Table_6[[#This Row],[CAT3]:[EXAM5]]) -> 0 | K3: 18 | L3: 20 | M3: 33 | N3: =SUM(K3:M3) -> 71 | O3: 17 | P3: 10 | Q3: 15 | R3: =SUM(O3:Q3) -> 42 | S3: 10 | T3: 3 | U3: 33 | V3: =SUM(S3:U3) -> 46 | W3: 11 | X3: 10 | Y3: 8 | Z3: =SUM(W3:Y3) -> 29 | AD3: =SUM(AA3:AC3) -> 0 | AE3: 10 | AF3: 12 | AG3: 57 | AH3: =SUM(AE3:AG3) -> 79 | AL3: =SUM(AI3:AK3) -> 0 | AM3: 20 | AN3: 20 | AO3: 47 | AP3: =SUM(AM3:AO3) -> 87 | AT3: =SUM(AQ3:AS3) -> 0 | AX3: =SUM(AU3:AW3) -> 0 | AY3: 20 | AZ3: 20 | BA3: 47 | BB3: =SUM(AY3:BA3) -> 87 | BC3: 10 | BD3: 20 | BE3: 31 | BF3: =SUM(BC3:BE3) -> 61 | BJ3: =SUM(BG3:BI3) -> 0 | BK3: 10 | BL3: 10 | BM3: 35 | BN3: =SUM(Table_6[[#This Row],[CAT59]:[EXAM61]]) -> 55 | BO3: 20 | BP3: 20 | BQ3: 30 | BR3: =SUM(BO3:BQ3) -> 70 | BV3: =SUM(BS3:BU3) -> 0
A4: ='[1]student detail'!A3 -> BDS/22/002 | B4: ='[1]student detail'!B3 -> AMADI OLUEBUBE TESTIMONY | C4: 10 | D4: 10 | E4: 54 | F4: =SUM(Table_6[[#This Row],[CAT]:[EXAM]]) -> 74 | J4: =SUM(Table_6[[#This Row],[CAT3]:[EXAM5]]) -> 0 | K4: 18 | L4: 20 | M4: 29 | N4: =SUM(K4:M4) -> 67 | O4: 10 | P4: 18 | Q4: 33 | R4: =SUM(O4:Q4) -> 61 | S4: 10 | T4: 18 | U4: 30 | V4: =SUM(S4:U4) -> 58 | W4: 10 | X4: 11 | Y4: 18 | Z4: =SUM(W4:Y4) -> 39 | AD4: =SUM(AA4:AC4) -> 0 | AE4: 8 | AF4: 10 | AG4: 52 | AH4: =SUM(AE4:AG4) -> 70 | AL4: =SUM(AI4:AK4) -> 0 | AM4: 20 | AN4: 29 | AO4: 34 | AP4: =SUM(AM4:AO4) -> 83 | AT4: =SUM(AQ4:AS4) -> 0 | AX4: =SUM(AU4:AW4) -> 0 | AY4: 20 | AZ4: 20 | BA4: 44 | BB4: =SUM(AY4:BA4) -> 84 | BC4: 10 | BD4: 29 | BE4: 36 | BF4: =SUM(BC4:BE4) -> 75 | BJ4: =SUM(BG4:BI4) -> 0 | BK4: 10 | BL4: 12 | BM4: 29 | BN4: =SUM(Table_6[[#This Row],[CAT59]:[EXAM61]]) -> 51 | BO4: 20 | BP4: 20 | BQ4: 41 | BR4: =SUM(BO4:BQ4) -> 81 | BV4: =SUM(BS4:BU4) -> 0
A5: ='[1]student detail'!A4 -> BDS/22/003 | B5: ='[1]student detail'!B4 -> AMAECHI BRIGHT | C5: 12 | E5: 17 | F5: =SUM(Table_6[[#This Row],[CAT]:[EXAM]]) -> 29 | J5: =SUM(Table_6[[#This Row],[CAT3]:[EXAM5]]) -> 0 | K5: 10 | L5: 18 | M5: 14 | N5: =SUM(K5:M5) -> 42 | O5: 11 | P5: 10 | Q5: 29 | R5: =SUM(O5:Q5) -> 50 | S5: 10 | T5: 9 | U5: 20 | V5: =SUM(S5:U5) -> 39 | W5: 10 | X5: 10 | Y5: 11 | Z5: =SUM(W5:Y5) -> 31 | AD5: =SUM(AA5:AC5) -> 0 | AE5: 10 | AF5: 5 | AG5: 18 | AH5: =SUM(AE5:AG5) -> 33 | AL5: =SUM(AI5:AK5) -> 0 | AM5: 20 | AN5: 17 | AO5: 24 | AP5: =SUM(AM5:AO5) -> 61 | AT5: =SUM(AQ5:AS5) -> 0 | AX5: =SUM(AU5:AW5) -> 0 | AY5: 20 | AZ5: 20 | BA5: 29 | BB5: =SUM(AY5:BA5) -> 69 | BC5: 10 | BD5: 17 | BE5: 30 | BF5: =SUM(BC5:BE5) -> 57 | BJ5: =SUM(BG5:BI5) -> 0 | BK5: 10 | BL5: 20 | BM5: 21 | BN5: =SUM(Table_6[[#This Row],[CAT59]:[EXAM61]]) -> 51 | BO5: 20 | BP5: 20 | BQ5: 29 | BR5: =SUM(BO5:BQ5) -> 69 | BV5: =SUM(BS5:BU5) -> 0
A6: ='[1]student detail'!A5 -> BDS/22/006 | B6: ='[1]student detail'!B5 -> ALOZIE CHIEMELA PROSPER | C6: 10 | D6: 12 | E6: 54 | F6: =SUM(Table_6[[#This Row],[CAT]:[EXAM]]) -> 76 | J6: =SUM(Table_6[[#This Row],[CAT3]:[EXAM5]]) -> 0 | K6: 15 | L6: 20 | M6: 22 | N6: =SUM(K6:M6) -> 57 | O6: 10 | P6: 14 | Q6: 31 | R6: =SUM(O6:Q6) -> 55 | S6: 10 | T6: 8 | U6: 30 | V6: =SUM(S6:U6) -> 48 | W6: 10 | X6: 8 | Y6: 20 | Z6: =SUM(W6:Y6) -> 38 | AD6: =SUM(AA6:AC6) -> 0 | AE6: 10 | AF6: 10 | AG6: 40 | AH6: =SUM(AE6:AG6) -> 60 | AL6: =SUM(AI6:AK6) -> 0 | AM6: 20 | AN6: 30 | AO6: 44 | AP6: =SUM(AM6:AO6) -> 94 | AT6: =SUM(AQ6:AS6) -> 0 | AX6: =SUM(AU6:AW6) -> 0 | AY6: 20 | AZ6: 20 | BA6: 48 | BB6: =SUM(AY6:BA6) -> 88 | BC6: 10 | BD6: 30 | BE6: 39 | BF6: =SUM(BC6:BE6) -> 79 | BJ6: =SUM(BG6:BI6) -> 0 | BK6: 10 | BL6: 10 | BM6: 32 | BN6: =SUM(Table_6[[#This Row],[CAT59]:[EXAM61]]) -> 52 | BO6: 20 | BP6: 20 | BQ6: 38 | BR6: =SUM(BO6:BQ6) -> 78 | BV6: =SUM(BS6:BU6) -> 0
A7: ='[1]student detail'!A6 -> BDS/22/007 | B7: ='[1]student detail'!B6 -> CHINEDU CHIDERA | C7: 10 | D7: 8 | E7: 38 | F7: =SUM(Table_6[[#This Row],[CAT]:[EXAM]]) -> 56 | J7: =SUM(Table_6[[#This Row],[CAT3]:[EXAM5]]) -> 0 | K7: 12 | L7: 20 | M7: 25 | N7: =SUM(K7:M7) -> 57 | O7: 10 | P7: 9 | Q7: 20 | R7: =SUM(O7:Q7) -> 39 | S7: 10 | T7: 11 | U7: 34 | V7: =SUM(S7:U7) -> 55 | W7: 10 | X7: 7 | Y7: 9 | Z7: =SUM(W7:Y7) -> 26 | AD7: =SUM(AA7:AC7) -> 0 | AE7: 10 | AF7: 8 | AG7: 58 | AH7: =SUM(AE7:AG7) -> 76 | AL7: =SUM(AI7:AK7) -> 0 | AM7: 20 | AN7: 17 | AO7: 21 | AP7: =SUM(AM7:AO7) -> 58 | AT7: =SUM(AQ7:AS7) -> 0 | AX7: =SUM(AU7:AW7) -> 0 | AY7: 20 | AZ7: 20 | BA7: 42 | BB7: =SUM(AY7:BA7) -> 82 | BC7: 10 | BD7: 17 | BE7: 33 | BF7: =SUM(BC7:BE7) -> 60 | BJ7: =SUM(BG7:BI7) -> 0 | BK7: 10 | BL7: 20 | BM7: 15 | BN7: =SUM(Table_6[[#This Row],[CAT59]:[EXAM61]]) -> 45 | BO7: 20 | BP7: 20 | BQ7: 30 | BR7: =SUM(BO7:BQ7) -> 70 | BV7: =SUM(BS7:BU7) -> 0
A8: ='[1]student detail'!A7 -> BDS/22/008 | B8: ='[1]student detail'!B7 -> CHIONYE BRIGHT | C8: 10 | D8: 8 | E8: 56 | F8: =SUM(Table_6[[#This Row],[CAT]:[EXAM]]) -> 74 | J8: =SUM(Table_6[[#This Row],[CAT3]:[EXAM5]]) -> 0 | K8: 15 | L8: 20 | M8: 37 | N8: =SUM(K8:M8) -> 72 | O8: 10 | P8: 19 | Q8: 33 | R8: =SUM(O8:Q8) -> 62 | S8: 10 | T8: 15 | U8: 37 | V8: =SUM(S8:U8) -> 62 | W8: 10 | X8: 16 | Y8: 28 | Z8: =SUM(W8:Y8) -> 54 | AD8: =SUM(AA8:AC8) -> 0 | AE8: 10 | AF8: 8 | AG8: 50 | AH8: =SUM(AE8:AG8) -> 68 | AL8: =SUM(AI8:AK8) -> 0 | AM8: 20 | AN8: 19 | AO8: 55 | AP8: =SUM(AM8:AO8) -> 94 | AT8: =SUM(AQ8:AS8) -> 0 | AX8: =SUM(AU8:AW8) -> 0 | AY8: 20 | AZ8: 20 | BA8: 49 | BB8: =SUM(AY8:BA8) -> 89 | BC8: 10 | BD8: 37 | BE8: 45 | BF8: =SUM(BC8:BE8) -> 92 | BJ8: =SUM(BG8:BI8) -> 0 | BK8: 10 | BL8: 10 | BM8: 50 | BN8: =SUM(Table_6[[#This Row],[CAT59]:[EXAM61]]) -> 70 | BO8: 20 | BP8: 20 | BQ8: 46 | BR8: =SUM(BO8:BQ8) -> 86 | BV8: =SUM(BS8:BU8) -> 0
A9: ='[1]student detail'!A8 -> BDS/22/010 | B9: ='[1]student detail'!B8 -> ENYINNAYA EXCEL MIRACLE | C9: 8 | D9: 10 | E9: 51 | F9: =SUM(Table_6[[#This Row],[CAT]:[EXAM]]) -> 69 | J9: =SUM(Table_6[[#This Row],[CAT3]:[EXAM5]]) -> 0 | K9: 12 | L9: 20 | M9: 39 | N9: =SUM(K9:M9) -> 71 | O9: 12 | P9: 10 | Q9: 24 | R9: =SUM(O9:Q9) -> 46 | S9: 10 | T9: 3 | U9: 30 | V9: =SUM(S9:U9) -> 43 | W9: 10 | X9: 10 | Y9: 20 | Z9: =SUM(W9:Y9) -> 40 | AD9: =SUM(AA9:AC9) -> 0 | AE9: 6 | AF9: 10 | AG9: 45 | AH9: =SUM(AE9:AG9) -> 61 | AL9: =SUM(AI9:AK9) -> 0 | AM9: 20 | AN9: 20 | AO9: 50 | AP9: =SUM(AM9:AO9) -> 90 | AT9: =SUM(AQ9:AS9) -> 0 | AX9: =SUM(AU9:AW9) -> 0 | AY9: 20 | AZ9: 20 | BA9: 47 | BB9: =SUM(AY9:BA9) -> 87 | BC9: 10 | BD9: 19 | BE9: 33 | BF9: =SUM(BC9:BE9) -> 62 | BJ9: =SUM(BG9:BI9) -> 0 | BK9: 10 | BL9: 20 | BM9: 30 | BN9: =SUM(Table_6[[#This Row],[CAT59]:[EXAM61]]) -> 60 | BO9: 20 | BP9: 20 | BQ9: 43 | BR9: =SUM(BO9:BQ9) -> 83 | BV9: =SUM(BS9:BU9) -> 0
A10: ='[1]student detail'!A9 -> BDS/22/012 | B10: ='[1]student detail'!B9 -> OGBONNAYA FAVOUR IFEOMA | C10: 10 | D10: 8 | E10: 40 | F10: =SUM(Table_6[[#This Row],[CAT]:[EXAM]]) -> 58 | J10: =SUM(Table_6[[#This Row],[CAT3]:[EXAM5]]) -> 0 | L10: 20 | M10: 38 | N10: =SUM(K10:M10) -> 58 | O10: 20 | P10: 15 | Q10: 29 | R10: =SUM(O10:Q10) -> 64 | S10: 10 | T10: 3 | U10: 52 | V10: =SUM(S10:U10) -> 65 | W10: 10 | X10: 17 | Y10: 14 | Z10: =SUM(W10:Y10) -> 41 | AD10: =SUM(AA10:AC10) -> 0 | AE10: 8 | AF10: 10 | AG10: 53 | AH10: =SUM(AE10:AG10) -> 71 | AL10: =SUM(AI10:AK10) -> 0 | AM10: 20 | AN10: 20 | AO10: 15 | AP10: =SUM(AM10:AO10) -> 55 | AT10: =SUM(AQ10:AS10) -> 0 | AX10: =SUM(AU10:AW10) -> 0 | AY10: 20 | AZ10: 20 | BA10: 36 | BB10: =SUM(AY10:BA10) -> 76 | BC10: 10 | BD10: 35 | BE10: 47 | BF10: =SUM(BC10:BE10) -> 92 | BJ10: =SUM(BG10:BI10) -> 0 | BK10: 10 | BL10: 23 | BM10: 32 | BN10: =SUM(Table_6[[#This Row],[CAT59]:[EXAM61]]) -> 65 | BO10: 20 | BP10: 20 | BQ10: 31 | BR10: =SUM(BO10:BQ10) -> 71 | BV10: =SUM(BS10:BU10) -> 0
A11: ='[1]student detail'!A10 -> BDS/22/013 | B11: ='[1]student detail'!B10 -> UBADIRE FORTUNE EMMANUEL | C11: 12 | D11: 10 | E11: 52 | F11: =SUM(Table_6[[#This Row],[CAT]:[EXAM]]) -> 74 | J11: =SUM(Table_6[[#This Row],[CAT3]:[EXAM5]]) -> 0 | K11: 18 | L11: 20 | M11: 35 | N11: =SUM(K11:M11) -> 73 | O11: 11 | P11: 10 | Q11: 46 | R11: =SUM(O11:Q11) -> 67 | S11: 10 | T11: 13 | U11: 30 | V11: =SUM(S11:U11) -> 53 | W11: 15 | X11: 10 | Y11: 34 | Z11: =SUM(W11:Y11) -> 59 | AD11: =SUM(AA11:AC11) -> 0 | AE11: 10 | AF11: 10 | AG11: 58 | AH11: =SUM(AE11:AG11) -> 78 | AL11: =SUM(AI11:AK11) -> 0 | AM11: 20 | AN11: 20 | AO11: 58 | AP11: =SUM(AM11:AO11) -> 98 | AT11: =SUM(AQ11:AS11) -> 0 | AX11: =SUM(AU11:AW11) -> 0 | AY11: 20 | AZ11: 20 | BA11: 45 | BB11: =SUM(AY11:BA11) -> 85 | BC11: 10 | BD11: 20 | BE11: 46 | BF11: =SUM(BC11:BE11) -> 76 | BJ11: =SUM(BG11:BI11) -> 0 | BK11: 10 | BL11: 20 | BM11: 36 | BN11: =SUM(Table_6[[#This Row],[CAT59]:[EXAM61]]) -> 66 | BO11: 20 | BP11: 20 | BQ11: 42 | BR11: =SUM(BO11:BQ11) -> 82 | BV11: =SUM(BS11:BU11) -> 0
A12: ='[1]student detail'!A11 -> BDS/22/015 | B12: ='[1]student detail'!B11 -> IHEME SOLOMON | C12: 13 | D12: 15 | E12: 55 | F12: =SUM(Table_6[[#This Row],[CAT]:[EXAM]]) -> 83 | J12: =SUM(Table_6[[#This Row],[CAT3]:[EXAM5]]) -> 0 | K12: 15 | L12: 20 | M12: 30 | N12: =SUM(K12:M12) -> 65 | O12: 20 | P12: 17 | Q12: 38 | R12: =SUM(O12:Q12) -> 75 | S12: 10 | T12: 3 | U12: 25 | V12: =SUM(S12:U12) -> 38 | W12: 10 | X12: 15 | Y12: 28 | Z12: =SUM(W12:Y12) -> 53 | AD12: =SUM(AA12:AC12) -> 0 | AE12: 10 | AF12: 10 | AG12: 38 | AH12: =SUM(AE12:AG12) -> 58 | AL12: =SUM(AI12:AK12) -> 0 | AM12: 20 | AN12: 19 | AO12: 53 | AP12: =SUM(AM12:AO12) -> 92 | AT12: =SUM(AQ12:AS12) -> 0 | AX12: =SUM(AU12:AW12) -> 0 | AY12: 20 | AZ12: 20 | BA12: 49 | BB12: =SUM(AY12:BA12) -> 89 | BC12: 10 | BD12: 36 | BE12: 47 | BF12: =SUM(BC12:BE12) -> 93 | BJ12: =SUM(BG12:BI12) -> 0 | BK12: 10 | BL12: 24 | BM12: 21 | BN12: =SUM(Table_6[[#This Row],[CAT59]:[EXAM61]]) -> 55 | BO12: 20 | BP12: 20 | BQ12: 40 | BR12: =SUM(BO12:BQ12) -> 80 | BV12: =SUM(BS12:BU12) -> 0
A13: ='[1]student detail'!A12 -> BDS/22/017 | B13: ='[1]student detail'!B12 -> IWUCHUKWU PRECIOUS | C13: 8 | D13: 10 | E13: 39 | F13: =SUM(Table_6[[#This Row],[CAT]:[EXAM]]) -> 57 | J13: =SUM(Table_6[[#This Row],[CAT3]:[EXAM5]]) -> 0 | K13: 17 | L13: 20 | M13: 21 | N13: =SUM(K13:M13) -> 58 | O13: 13 | P13: 10 | Q13: 29 | R13: =SUM(O13:Q13) -> 52 | S13: 10 | T13: 13 | U13: 25 | V13: =SUM(S13:U13) -> 48 | W13: 10 | X13: 7 | Y13: 6 | Z13: =SUM(W13:Y13) -> 23 | AD13: =SUM(AA13:AC13) -> 0 | AE13: 8 | AF13: 8 | AG13: 59 | AH13: =SUM(AE13:AG13) -> 75 | AL13: =SUM(AI13:AK13) -> 0 | AM13: 20 | AN13: 19 | AO13: 20 | AP13: =SUM(AM13:AO13) -> 59 | AT13: =SUM(AQ13:AS13) -> 0 | AX13: =SUM(AU13:AW13) -> 0 | AY13: 20 | AZ13: 20 | BA13: 41 | BB13: =SUM(AY13:BA13) -> 81 | BC13: 10 | BD13: 20 | BE13: 21 | BF13: =SUM(BC13:BE13) -> 51 | BJ13: =SUM(BG13:BI13) -> 0 | BK13: 10 | BL13: 20 | BM13: 20 | BN13: =SUM(Table_6[[#This Row],[CAT59]:[EXAM61]]) -> 50 | BO13: 20 | BP13: 20 | BQ13: 31 | BR13: =SUM(BO13:BQ13) -> 71 | BV13: =SUM(BS13:BU13) -> 0
A14: ='[1]student detail'!A13 -> BDS/22/019 | B14: ='[1]student detail'!B13 -> KELECHI KING DAVID | C14: 12 | D14: 6 | E14: 49 | F14: =SUM(Table_6[[#This Row],[CAT]:[EXAM]]) -> 67 | J14: =SUM(Table_6[[#This Row],[CAT3]:[EXAM5]]) -> 0 | K14: 16 | L14: 8 | M14: 17 | N14: =SUM(K14:M14) -> 41 | O14: 10 | P14: 12 | Q14: 27 | R14: =SUM(O14:Q14) -> 49 | S14: 10 | T14: 17 | U14: 30 | V14: =SUM(S14:U14) -> 57 | W14: 10 | X14: 10 | Y14: 12 | Z14: =SUM(W14:Y14) -> 32 | AD14: =SUM(AA14:AC14) -> 0 | AH14: =SUM(AE14:AG14) -> 0 | AL14: =SUM(AI14:AK14) -> 0 | AM14: 20 | AN14: 10 | AO14: 22 | AP14: =SUM(AM14:AO14) -> 52 | AT14: =SUM(AQ14:AS14) -> 0 | AX14: =SUM(AU14:AW14) -> 0 | AY14: 20 | AZ14: 20 | BA14: 48 | BB14: =SUM(AY14:BA14) -> 88 | BC14: 10 | BD14: 20 | BE14: 25 | BF14: =SUM(BC14:BE14) -> 55 | BJ14: =SUM(BG14:BI14) -> 0 | BK14: 10 | BL14: 20 | BM14: 20 | BN14: =SUM(Table_6[[#This Row],[CAT59]:[EXAM61]]) -> 50 | BO14: 20 | BP14: 20 | BQ14: 44 | BR14: =SUM(BO14:BQ14) -> 84 | BV14: =SUM(BS14:BU14) -> 0
A15: ='[1]student detail'!A14 -> BDS/22/021 | B15: ='[1]student detail'!B14 -> NDUBUISI CHISOM | C15: 10 | D15: 12 | E15: 54 | F15: =SUM(Table_6[[#This Row],[CAT]:[EXAM]]) -> 76 | J15: =SUM(Table_6[[#This Row],[CAT3]:[EXAM5]]) -> 0 | K15: 16 | L15: 20 | M15: 46 | N15: =SUM(K15:M15) -> 82 | O15: 17 | P15: 20 | Q15: 33 | R15: =SUM(O15:Q15) -> 70 | S15: 10 | T15: 18 | U15: 55 | V15: =SUM(S15:U15) -> 83 | W15: 10 | X15: 17 | Y15: 34 | Z15: =SUM(W15:Y15) -> 61 | AD15: =SUM(AA15:AC15) -> 0 | AE15: 8 | AF15: 10 | AG15: 60 | AH15: =SUM(AE15:AG15) -> 78 | AL15: =SUM(AI15:AK15) -> 0 | AM15: 20 | AN15: 20 | AO15: 53 | AP15: =SUM(AM15:AO15) -> 93 | AT15: =SUM(AQ15:AS15) -> 0 | AX15: =SUM(AU15:AW15) -> 0 | AY15: 20 | AZ15: 20 | BA15: 55 | BB15: =SUM(AY15:BA15) -> 95 | BC15: 10 | BD15: 18 | BE15: 42 | BF15: =SUM(BC15:BE15) -> 70 | BJ15: =SUM(BG15:BI15) -> 0 | BK15: 10 | BL15: 20 | BM15: 40 | BN15: =SUM(Table_6[[#This Row],[CAT59]:[EXAM61]]) -> 70 | BO15: 20 | BP15: 20 | BQ15: 53 | BR15: =SUM(BO15:BQ15) -> 93 | BV15: =SUM(BS15:BU15) -> 0
A16: ='[1]student detail'!A15 -> BDS/22/023 | B16: ='[1]student detail'!B15 -> NDULAKA CHIMAMANDA | C16: 10 | D16: 10 | E16: 54 | F16: =SUM(Table_6[[#This Row],[CAT]:[EXAM]]) -> 74 | J16: =SUM(Table_6[[#This Row],[CAT3]:[EXAM5]]) -> 0 | K16: 16 | L16: 20 | M16: 30 | N16: =SUM(K16:M16) -> 66 | O16: 20 | P16: 10 | Q16: 41 | R16: =SUM(O16:Q16) -> 71 | S16: 10 | T16: 16 | U16: 36 | V16: =SUM(S16:U16) -> 62 | W16: 10 | X16: 18 | Y16: 32 | Z16: =SUM(W16:Y16) -> 60 | AA16: 2 | AD16: =SUM(AA16:AC16) -> 2 | AE16: 10 | AF16: 10 | AG16: 52 | AH16: =SUM(AE16:AG16) -> 72 | AL16: =SUM(AI16:AK16) -> 0 | AM16: 20 | AN16: 18 | AO16: 54 | AP16: =SUM(AM16:AO16) -> 92 | AT16: =SUM(AQ16:AS16) -> 0 | AX16: =SUM(AU16:AW16) -> 0 | AY16: 20 | AZ16: 20 | BA16: 45 | BB16: =SUM(AY16:BA16) -> 85 | BC16: 10 | BD16: 20 | BE16: 44 | BF16: =SUM(BC16:BE16) -> 74 | BJ16: =SUM(BG16:BI16) -> 0 | BK16: 10 | BL16: 25 | BM16: 47 | BN16: =SUM(Table_6[[#This Row],[CAT59]:[EXAM61]]) -> 82 | BO16: 20 | BP16: 20 | BQ16: 48 | BR16: =SUM(BO16:BQ16) -> 88 | BV16: =SUM(BS16:BU16) -> 0
A17: ='[1]student detail'!A16 -> BDS/22/026 | B17: ='[1]student detail'!B16 -> OKORO WINNER | C17: 10 | D17: 12 | E17: 54 | F17: =SUM(Table_6[[#This Row],[CAT]:[EXAM]]) -> 76 | J17: =SUM(Table_6[[#This Row],[CAT3]:[EXAM5]]) -> 0 | K17: 19 | L17: 20 | M17: 40 | N17: 79 | O17: 10 | P17: 13 | Q17: 48 | R17: =SUM(O17:Q17) -> 71 | S17: 10 | T17: 16 | U17: 25 | V17: =SUM(S17:U17) -> 51 | W17: 11 | X17: 11 | Y17: 28 | Z17: =SUM(W17:Y17) -> 50 | AD17: =SUM(AA17:AC17) -> 0 | AE17: 10 | AF17: 12 | AG17: 40 | AH17: =SUM(AE17:AG17) -> 62 | AL17: =SUM(AI17:AK17) -> 0 | AM17: 20 | AN17: 20 | AO17: 48 | AP17: =SUM(AM17:AO17) -> 88 | AT17: =SUM(AQ17:AS17) -> 0 | AX17: =SUM(AU17:AW17) -> 0 | AY17: 20 | AZ17: 20 | BA17: 50 | BB17: =SUM(AY17:BA17) -> 90 | BC17: 10 | BD17: 30 | BE17: 44 | BF17: =SUM(BC17:BE17) -> 84 | BJ17: =SUM(BG17:BI17) -> 0 | BK17: 10 | BL17: 14 | BM17: 48 | BN17: =SUM(Table_6[[#This Row],[CAT59]:[EXAM61]]) -> 72 | BO17: 20 | BP17: 20 | BQ17: 43 | BR17: =SUM(BO17:BQ17) -> 83 | BV17: =SUM(BS17:BU17) -> 0
A18: ='[1]student detail'!A17 -> BDS/22/027 | B18: ='[1]student detail'!B17 -> ONONOBI AMARACHI | C18: 10 | D18: 10 | E18: 43 | F18: =SUM(Table_6[[#This Row],[CAT]:[EXAM]]) -> 63 | J18: =SUM(Table_6[[#This Row],[CAT3]:[EXAM5]]) -> 0 | K18: 18 | L18: 20 | M18: 41 | N18: =SUM(K18:M18) -> 79 | O18: 17 | P18: 20 | Q18: 29 | R18: =SUM(O18:Q18) -> 66 | S18: 10 | T18: 17 | U18: 35 | V18: =SUM(S18:U18) -> 62 | W18: 11 | X18: 12 | Y18: 15 | Z18: =SUM(W18:Y18) -> 38 | AD18: =SUM(AA18:AC18) -> 0 | AE18: 8 | AF18: 10 | AG18: 56 | AH18: =SUM(AE18:AG18) -> 74 | AL18: =SUM(AI18:AK18) -> 0 | AM18: 20 | AN18: 20 | AO18: 38 | AP18: =SUM(AM18:AO18) -> 78 | AT18: =SUM(AQ18:AS18) -> 0 | AX18: =SUM(AU18:AW18) -> 0 | AY18: 20 | AZ18: 20 | BA18: 36 | BB18: =SUM(AY18:BA18) -> 76 | BC18: 10 | BD18: 27 | BE18: 23 | BF18: =SUM(BC18:BE18) -> 60 | BJ18: =SUM(BG18:BI18) -> 0 | BK18: 10 | BL18: 21 | BM18: 27 | BN18: =SUM(Table_6[[#This Row],[CAT59]:[EXAM61]]) -> 58 | BO18: 20 | BP18: 20 | BQ18: 22 | BR18: =SUM(BO18:BQ18) -> 62 | BV18: =SUM(BS18:BU18) -> 0
A19: ='[1]student detail'!A18 -> BDS/22/029 | B19: ='[1]student detail'!B18 -> RICHARD GOODLUCK | C19: 10 | D19: 8 | E19: 56 | F19: =SUM(Table_6[[#This Row],[CAT]:[EXAM]]) -> 74 | J19: =SUM(Table_6[[#This Row],[CAT3]:[EXAM5]]) -> 0 | K19: 10 | L19: 10 | M19: 28 | N19: =SUM(K19:M19) -> 48 | O19: 5 | P19: 5 | Q19: 39 | R19: =SUM(O19:Q19) -> 49 | S19: 10 | T19: 8 | U19: 30 | V19: =SUM(S19:U19) -> 48 | W19: 11 | X19: 10 | Y19: 12 | Z19: =SUM(W19:Y19) -> 33 | AD19: =SUM(AA19:AC19) -> 0 | AE19: 5 | AF19: 10 | AG19: 46 | AH19: =SUM(AE19:AG19) -> 61 | AL19: =SUM(AI19:AK19) -> 0 | AM19: 20 | AN19: 20 | AO19: 28 | AP19: =SUM(AM19:AO19) -> 68 | AT19: =SUM(AQ19:AS19) -> 0 | AX19: =SUM(AU19:AW19) -> 0 | AY19: 20 | AZ19: 20 | BA19: 42 | BB19: =SUM(AY19:BA19) -> 82 | BC19: 10 | BD19: 23 | BE19: 35 | BF19: =SUM(BC19:BE19) -> 68 | BJ19: =SUM(BG19:BI19) -> 0 | BK19: 10 | BL19: 20 | BM19: 20 | BN19: =SUM(Table_6[[#This Row],[CAT59]:[EXAM61]]) -> 50 | BO19: 20 | BP19: 20 | BQ19: 41 | BR19: =SUM(BO19:BQ19) -> 81 | BV19: =SUM(BS19:BU19) -> 0
A20: ='[1]student detail'!A19 -> BDS/22/033 | B20: ='[1]student detail'!B19 -> UKPABI NOBLE MUNACHI | C20: 12 | D20: 8 | E20: 47 | F20: =SUM(Table_6[[#This Row],[CAT]:[EXAM]]) -> 67 | J20: =SUM(Table_6[[#This Row],[CAT3]:[EXAM5]]) -> 0 | K20: 14 | L20: 20 | M20: 25 | N20: =SUM(K20:M20) -> 59 | O20: 10 | P20: 12 | Q20: 37 | R20: =SUM(O20:Q20) -> 59 | S20: 10 | T20: 17 | U20: 30 | V20: =SUM(S20:U20) -> 57 | W20: 10 | X20: 11 | Y20: 20 | Z20: =SUM(W20:Y20) -> 41 | AD20: =SUM(AA20:AC20) -> 0 | AE20: 10 | AF20: 12 | AG20: 53 | AH20: =SUM(AE20:AG20) -> 75 | AL20: =SUM(AI20:AK20) -> 0 | AM20: 20 | AN20: 20 | AO20: 37 | AP20: =SUM(AM20:AO20) -> 77 | AT20: =SUM(AQ20:AS20) -> 0 | AX20: =SUM(AU20:AW20) -> 0 | AY20: 20 | AZ20: 20 | BA20: 50 | BB20: =SUM(AY20:BA20) -> 90 | BC20: 10 | BD20: 20 | BE20: 39 | BF20: =SUM(BC20:BE20) -> 69 | BJ20: =SUM(BG20:BI20) -> 0 | BK20: 10 | BL20: 20 | BM20: 25 | BN20: =SUM(Table_6[[#This Row],[CAT59]:[EXAM61]]) -> 55 | BO20: 20 | BP20: 20 | BQ20: 35 | BR20: =SUM(BO20:BQ20) -> 75 | BV20: =SUM(BS20:BU20) -> 0
A21: ='[1]student detail'!A20 -> BDS/22/034 | B21: ='[1]student detail'!B20 -> VICTOR VICTORY | C21: 10 | D21: 12 | E21: 54 | F21: =SUM(Table_6[[#This Row],[CAT]:[EXAM]]) -> 76 | J21: =SUM(Table_6[[#This Row],[CAT3]:[EXAM5]]) -> 0 | K21: 19 | L21: 20 | M21: 30 | N21: =SUM(K21:M21) -> 69 | O21: 17 | P21: 20 | Q21: 51 | R21: =SUM(O21:Q21) -> 88 | S21: 10 | T21: 18 | U21: 35 | V21: =SUM(S21:U21) -> 63 | W21: 11 | X21: 20 | Y21: 20 | Z21: =SUM(W21:Y21) -> 51 | AD21: =SUM(AA21:AC21) -> 0 | AE21: 10 | AF21: 10 | AG21: 45 | AH21: =SUM(AE21:AG21) -> 65 | AL21: =SUM(AI21:AK21) -> 0 | AM21: 20 | AN21: 20 | AO21: 52 | AP21: =SUM(AM21:AO21) -> 92 | AT21: =SUM(AQ21:AS21) -> 0 | AX21: =SUM(AU21:AW21) -> 0 | AY21: 20 | AZ21: 20 | BA21: 51 | BB21: =SUM(AY21:BA21) -> 91 | BC21: 10 | BD21: 39 | BE21: 33 | BF21: 0 | BJ21: =SUM(BG21:BI21) -> 0 | BK21: 10 | BL21: 20 | BM21: 30 | BN21: =SUM(Table_6[[#This Row],[CAT59]:[EXAM61]]) -> 60 | BO21: 20 | BP21: 20 | BQ21: 47 | BR21: =SUM(BO21:BQ21) -> 87 | BV21: =SUM(BS21:BU21) -> 0
A22: ='[1]student detail'!A21 -> BDS/22/036 | B22: ='[1]student detail'!B21 -> CHIBUZOR WISDOM | C22: 10 | D22: 10 | E22: 48 | J22: =SUM(Table_6[[#This Row],[CAT3]:[EXAM5]]) -> 0 | K22: 15 | L22: 20 | M22: 21 | N22: =SUM(K22:M22) -> 56 | O22: 10 | P22: 11 | Q22: 35 | R22: =SUM(O22:Q22) -> 56 | S22: 10 | T22: 8 | U22: 20 | V22: =SUM(S22:U22) -> 38 | W22: 10 | X22: 11 | Y22: 7 | Z22: =SUM(W22:Y22) -> 28 | AD22: =SUM(AA22:AC22) -> 0 | AE22: 12 | AF22: 8 | AG22: 25 | AH22: =SUM(AE22:AG22) -> 45 | AL22: =SUM(AI22:AK22) -> 0 | AM22: 20 | AN22: 19 | AO22: 56 | AP22: =SUM(AM22:AO22) -> 95 | AT22: =SUM(AQ22:AS22) -> 0 | AX22: =SUM(AU22:AW22) -> 0 | AY22: 20 | AZ22: 20 | BA22: 49 | BB22: =SUM(AY22:BA22) -> 89 | BC22: 10 | BD22: 17 | BE22: 41 | BJ22: =SUM(BG22:BI22) -> 0 | BK22: 10 | BL22: 20 | BM22: 17 | BN22: =SUM(Table_6[[#This Row],[CAT59]:[EXAM61]]) -> 47 | BO22: 20 | BP22: 20 | BQ22: 32 | BR22: =SUM(BO22:BQ22) -> 72 | BV22: =SUM(BS22:BU22) -> 0
A23: ='[1]student detail'!A22 -> BDS/22/038 | B23: ='[1]student detail'!B22 -> EMMANUEL CHISOM MICHAEL | C23: 10 | D23: 5 | E23: 18 | F23: =SUM(Table_6[[#This Row],[CAT]:[EXAM]]) -> 33 | J23: =SUM(Table_6[[#This Row],[CAT3]:[EXAM5]]) -> 0 | K23: 10 | L23: 20 | M23: 31 | N23: =SUM(K23:M23) -> 61 | O23: 5 | P23: 5 | Q23: 31 | R23: =SUM(O23:Q23) -> 41 | S23: 10 | T23: 7 | U23: 20 | V23: =SUM(S23:U23) -> 37 | W23: 5 | X23: 10 | Y23: 17 | Z23: =SUM(W23:Y23) -> 32 | AD23: =SUM(AA23:AC23) -> 0 | AE23: 10 | AF23: 10 | AG23: 18 | AH23: =SUM(AE23:AG23) -> 38 | AL23: =SUM(AI23:AK23) -> 0 | AM23: 20 | AN23: 20 | AO23: 31 | AP23: =SUM(AM23:AO23) -> 71 | AT23: =SUM(AQ23:AS23) -> 0 | AX23: =SUM(AU23:AW23) -> 0 | AY23: 20 | AZ23: 20 | BA23: 52 | BB23: =SUM(AY23:BA23) -> 92 | BC23: 10 | BD23: 26 | BE23: 25 | BF23: 0 | BJ23: =SUM(BG23:BI23) -> 0 | BK23: 10 | BL23: 20 | BM23: 25 | BN23: =SUM(Table_6[[#This Row],[CAT59]:[EXAM61]]) -> 55 | BO23: 20 | BP23: 20 | BQ23: 39 | BR23: =SUM(BO23:BQ23) -> 79 | BV23: =SUM(BS23:BU23) -> 0
A24: ='[1]student detail'!A23 -> BDS/22/043 | B24: ='[1]student detail'!B23 -> Chidiebube Joshua Ikechukwu | C24: 5 | D24: 10 | E24: 10 | F24: =SUM(Table_6[[#This Row],[CAT]:[EXAM]]) -> 25 | J24: =SUM(Table_6[[#This Row],[CAT3]:[EXAM5]]) -> 0 | K24: 10 | L24: 20 | M24: 9 | N24: =SUM(K24:M24) -> 39 | O24: 10 | P24: 9 | Q24: 11 | R24: =SUM(O24:Q24) -> 30 | S24: 10 | T24: 11 | U24: 20 | V24: =SUM(S24:U24) -> 41 | W24: 8 | X24: 9 | Y24: 14 | Z24: =SUM(W24:Y24) -> 31 | AD24: =SUM(AA24:AC24) -> 0 | AE24: 10 | AF24: 10 | AG24: 18 | AH24: =SUM(AE24:AG24) -> 38 | AL24: =SUM(AI24:AK24) -> 0 | AM24: 20 | AN24: 20 | AO24: 30 | AP24: =SUM(AM24:AO24) -> 70 | AT24: =SUM(AQ24:AS24) -> 0 | AX24: =SUM(AU24:AW24) -> 0 | AY24: 20 | AZ24: 20 | BA24: 27 | BB24: =SUM(AY24:BA24) -> 67 | BC24: 10 | BD24: 14 | BE24: 22 | BF24: 0 | BJ24: =SUM(BG24:BI24) -> 0 | BK24: 10 | BL24: 20 | BM24: 10 | BN24: =SUM(Table_6[[#This Row],[CAT59]:[EXAM61]]) -> 40 | BO24: 20 | BP24: 20 | BQ24: 24 | BR24: =SUM(BO24:BQ24) -> 64 | BV24: =SUM(BS24:BU24) -> 0
A25: ='[1]student detail'!A24 -> BDS/22/046 | B25: ='[1]student detail'!B24 -> Lawrence Chibuike Prince | C25: 10 | D25: 15 | E25: 44 | F25: =SUM(Table_6[[#This Row],[CAT]:[EXAM]]) -> 69 | J25: =SUM(Table_6[[#This Row],[CAT3]:[EXAM5]]) -> 0 | K25: 14 | L25: 20 | M25: 26 | N25: =SUM(K25:M25) -> 60 | O25: 12 | P25: 10 | Q25: 30 | R25: =SUM(O25:Q25) -> 52 | S25: 10 | T25: 15 | U25: 45 | V25: =SUM(S25:U25) -> 70 | W25: 12 | X25: 12 | Y25: 12 | Z25: =SUM(W25:Y25) -> 36 | AD25: =SUM(AA25:AC25) -> 0 | AE25: 10 | AF25: 10 | AG25: 48 | AH25: =SUM(AE25:AG25) -> 68 | AL25: =SUM(AI25:AK25) -> 0 | AM25: 20 | AN25: 20 | AO25: 10 | AP25: =SUM(AM25:AO25) -> 50 | AT25: =SUM(AQ25:AS25) -> 0 | AX25: =SUM(AU25:AW25) -> 0 | AY25: 20 | AZ25: 20 | BA25: 58 | BB25: =SUM(AY25:BA25) -> 98 | BC25: 10 | BD25: 27 | BE25: 26 | BF25: 0 | BJ25: =SUM(BG25:BI25) -> 0 | BK25: 10 | BL25: 10 | BM25: 33 | BN25: =SUM(Table_6[[#This Row],[CAT59]:[EXAM61]]) -> 53 | BR25: =SUM(BO25:BQ25) -> 0 | BV25: =SUM(BS25:BU25) -> 0
A26: ='[1]student detail'!A25 -> BDS/22/047 | B26: ='[1]student detail'!B25 -> Onyema FAVOUR ADAEZE | C26: 10 | D26: 12 | E26: 52 | F26: =SUM(Table_6[[#This Row],[CAT]:[EXAM]]) -> 74 | J26: =SUM(Table_6[[#This Row],[CAT3]:[EXAM5]]) -> 0 | K26: 19 | L26: 20 | M26: 39 | N26: =SUM(K26:M26) -> 78 | O26: 20 | P26: 10 | Q26: 42 | R26: =SUM(O26:Q26) -> 72 | S26: 10 | T26: 18 | U26: 45 | V26: =SUM(S26:U26) -> 73 | W26: 17 | X26: 10 | Y26: 27 | Z26: =SUM(W26:Y26) -> 54 | AD26: =SUM(AA26:AC26) -> 0 | AE26: 8 | AF26: 8 | AG26: 55 | AH26: =SUM(AE26:AG26) -> 71 | AL26: =SUM(AI26:AK26) -> 0 | AM26: 20 | AN26: 19 | AO26: 58 | AP26: =SUM(AM26:AO26) -> 97 | AT26: =SUM(AQ26:AS26) -> 0 | AX26: =SUM(AU26:AW26) -> 0 | AY26: 20 | AZ26: 20 | BA26: 52 | BC26: 10 | BD26: 30 | BE26: 47 | BF26: 0 | BJ26: =SUM(BG26:BI26) -> 0 | BK26: 10 | BL26: 20 | BM26: 33 | BN26: =SUM(Table_6[[#This Row],[CAT59]:[EXAM61]]) -> 63 | BR26: =SUM(BO26:BQ26) -> 0 | BV26: =SUM(BS26:BU26) -> 0
A27: ='[1]student detail'!A26 -> BDS/22/053 | B27: ='[1]student detail'!B26 -> JOSEPH CHIDERA | C27: 10 | D27: 8 | E27: 57 | F27: =SUM(Table_6[[#This Row],[CAT]:[EXAM]]) -> 75 | J27: =SUM(Table_6[[#This Row],[CAT3]:[EXAM5]]) -> 0 | K27: 8 | L27: 10 | M27: 13 | N27: =SUM(K27:M27) -> 31 | O27: 13 | P27: 20 | Q27: 53 | R27: =SUM(O27:Q27) -> 86 | S27: 10 | T27: 21 | U27: 50 | V27: =SUM(S27:U27) -> 81 | W27: 11 | X27: 11 | Y27: 38 | Z27: =SUM(W27:Y27) -> 60 | AD27: =SUM(AA27:AC27) -> 0 | AE27: 10 | AF27: 8 | AG27: 60 | AH27: =SUM(AE27:AG27) -> 78 | AL27: =SUM(AI27:AK27) -> 0 | AM27: 20 | AN27: 26 | AO27: 54 | AP27: =SUM(AM27:AO27) -> 100 | AT27: =SUM(AQ27:AS27) -> 0 | AX27: =SUM(AU27:AW27) -> 0 | AY27: 20 | AZ27: 20 | BA27: 50 | BB27: =SUM(AY27:BA27) -> 90 | BC27: 10 | BD27: 30 | BE27: 48 | BF27: =SUM(BC27:BE27) -> 88 | BJ27: =SUM(BG27:BI27) -> 0 | BK27: 10 | BL27: 10 | BM27: 53 | BN27: =SUM(Table_6[[#This Row],[CAT59]:[EXAM61]]) -> 73 | BO27: 20 | BP27: 20 | BQ27: 45 | BR27: =SUM(BO27:BQ27) -> 85 | BV27: =SUM(BS27:BU27) -> 0
A28: ='[1]student detail'!A27 -> BDS/22/054 | B28: ='[1]student detail'!B27 -> KINGSELY GOSPEL | C28: 8 | D28: 8 | E28: 14 | F28: =SUM(Table_6[[#This Row],[CAT]:[EXAM]]) -> 30 | J28: =SUM(Table_6[[#This Row],[CAT3]:[EXAM5]]) -> 0 | K28: 2 | L28: 20 | M28: 9 | N28: =SUM(K28:M28) -> 31 | R28: =SUM(O28:Q28) -> 0 | S28: 10 | T28: 2 | U28: 20 | V28: =SUM(S28:U28) -> 32 | W28: 10 | X28: 7 | Y28: 4 | Z28: =SUM(W28:Y28) -> 21 | AD28: =SUM(AA28:AC28) -> 0 | AH28: =SUM(AE28:AG28) -> 0 | AL28: =SUM(AI28:AK28) -> 0 | AM28: 10 | AN28: 20 | AO28: 21 | AP28: =SUM(AM28:AO28) -> 51 | AT28: =SUM(AQ28:AS28) -> 0 | AX28: =SUM(AU28:AW28) -> 0 | AY28: 20 | AZ28: 20 | BA28: 23 | BB28: =SUM(AY28:BA28) -> 63 | BC28: 10 | BD28: 18 | BE28: 33 | BF28: =SUM(BC28:BE28) -> 61 | BJ28: =SUM(BG28:BI28) -> 0 | BK28: 10 | BL28: 20 | BM28: 14 | BN28: =SUM(Table_6[[#This Row],[CAT59]:[EXAM61]]) -> 44 | BO28: 20 | BP28: 20 | BQ28: 20 | BR28: 0 | BV28: =SUM(BS28:BU28) -> 0
A29: ='[1]student detail'!A28 -> BDS/22/059 | B29: ='[1]student detail'!B28 -> OBIOMA WISDOM | C29: 10 | D29: 6 | E29: 38 | F29: =SUM(Table_6[[#This Row],[CAT]:[EXAM]]) -> 54 | J29: =SUM(Table_6[[#This Row],[CAT3]:[EXAM5]]) -> 0 | K29: 8 | L29: 10 | M29: 13 | N29: =SUM(K29:M29) -> 31 | O29: 10 | P29: 1 | Q29: 4 | R29: =SUM(O29:Q29) -> 15 | S29: 10 | T29: 3 | U29: 20 | V29: =SUM(S29:U29) -> 33 | W29: 7 | X29: 7 | Y29: 5 | Z29: =SUM(W29:Y29) -> 19 | AD29: =SUM(AA29:AC29) -> 0 | AE29: 10 | AF29: 5 | AG29: 30 | AH29: =SUM(AE29:AG29) -> 45 | AL29: =SUM(AI29:AK29) -> 0 | AM29: 20 | AN29: 5 | AO29: 13 | AP29: =SUM(AM29:AO29) -> 38 | AT29: =SUM(AQ29:AS29) -> 0 | AX29: =SUM(AU29:AW29) -> 0 | AY29: 20 | AZ29: 20 | BA29: 47 | BB29: =SUM(AY29:BA29) -> 87 | BC29: 10 | BD29: 18 | BE29: 44 | BF29: =SUM(BC29:BE29) -> 72 | BJ29: =SUM(BG29:BI29) -> 0 | BK29: 10 | BL29: 20 | BM29: 48 | BN29: =SUM(Table_6[[#This Row],[CAT59]:[EXAM61]]) -> 78 | BO29: 20 | BP29: 20 | BQ29: 29 | BR29: =SUM(BO29:BQ29) -> 69 | BV29: =SUM(BS29:BU29) -> 0
A30: ='[1]student detail'!A29 -> BDS/22/060 | B30: ='[1]student detail'!B29 -> UKONMADU GOODLUCK | C30: 11 | D30: 10 | E30: 32 | F30: =SUM(Table_6[[#This Row],[CAT]:[EXAM]]) -> 53 | J30: =SUM(Table_6[[#This Row],[CAT3]:[EXAM5]]) -> 0 | K30: 16 | L30: 20 | M30: 32 | N30: =SUM(K30:M30) -> 68 | O30: 10 | P30: 16 | Q30: 17 | R30: =SUM(O30:Q30) -> 43 | S30: 10 | T30: 13 | U30: 39 | V30: =SUM(S30:U30) -> 62 | W30: 8 | X30: 7 | Y30: 14 | Z30: =SUM(W30:Y30) -> 29 | AD30: =SUM(AA30:AC30) -> 0 | AH30: =SUM(AE30:AG30) -> 0 | AL30: =SUM(AI30:AK30) -> 0 | AP30: =SUM(AM30:AO30) -> 0 | AT30: =SUM(AQ30:AS30) -> 0 | AX30: =SUM(AU30:AW30) -> 0 | AY30: 20 | AZ30: 20 | BA30: 33 | BB30: =SUM(AY30:BA30) -> 73 | BC30: 10 | BD30: 20 | BE30: 38 | BF30: =SUM(BC30:BE30) -> 68 | BJ30: =SUM(BG30:BI30) -> 0 | BK30: 10 | BL30: 20 | BM30: 13 | BN30: =SUM(Table_6[[#This Row],[CAT59]:[EXAM61]]) -> 43 | BO30: 20 | BP30: 20 | BQ30: 27 | BR30: =SUM(BO30:BQ30) -> 67 | BV30: =SUM(BS30:BU30) -> 0
A31: ='[1]student detail'!A30 -> BDS/22/061 | B31: ='[1]student detail'!B30 -> CHIAZOR VIVIAN | C31: 15 | D31: 8 | E31: 50 | F31: =SUM(Table_6[[#This Row],[CAT]:[EXAM]]) -> 73 | J31: =SUM(Table_6[[#This Row],[CAT3]:[EXAM5]]) -> 0 | K31: 18 | L31: 20 | M31: 45 | N31: =SUM(K31:M31) -> 83 | O31: 20 | P31: 18 | Q31: 53 | R31: =SUM(O31:Q31) -> 91 | S31: 10 | T31: 13 | U31: 39 | V31: =SUM(S31:U31) -> 62 | W31: 10 | X31: 17 | Y31: 28 | Z31: =SUM(W31:Y31) -> 55 | AD31: =SUM(AA31:AC31) -> 0 | AE31: 12 | AF31: 8 | AG31: 53 | AH31: =SUM(AE31:AG31) -> 73 | AL31: =SUM(AI31:AK31) -> 0 | AM31: 20 | AN31: 19 | AO31: 55 | AP31: =SUM(AM31:AO31) -> 94 | AT31: =SUM(AQ31:AS31) -> 0 | AX31: =SUM(AU31:AW31) -> 0 | AY31: 20 | AZ31: 20 | BA31: 55 | BB31: =SUM(AY31:BA31) -> 95 | BC31: 10 | BD31: 40 | BE31: 44 | BF31: =SUM(BC31:BE31) -> 94 | BJ31: =SUM(BG31:BI31) -> 0 | BK31: 10 | BL31: 10 | BM31: 48 | BN31: =SUM(Table_6[[#This Row],[CAT59]:[EXAM61]]) -> 68 | BO31: 20 | BP31: 20 | BQ31: 45 | BR31: =SUM(BO31:BQ31) -> 85 | BV31: =SUM(BS31:BU31) -> 0
A32: ='[1]student detail'!A31 -> BDS/22/062 | B32: ='[1]student detail'!B31 -> UGORJI DEBORAH | C32: 12 | D32: 9 | E32: 50 | F32: =SUM(Table_6[[#This Row],[CAT]:[EXAM]]) -> 71 | J32: =SUM(Table_6[[#This Row],[CAT3]:[EXAM5]]) -> 0 | K32: 18 | L32: 20 | M32: 20 | N32: =SUM(K32:M32) -> 58 | O32: 18 | P32: 20 | Q32: 28 | R32: =SUM(O32:Q32) -> 66 | S32: 12 | T32: 10 | U32: 40 | V32: =SUM(S32:U32) -> 62 | W32: 18 | X32: 10 | Y32: 19 | Z32: =SUM(W32:Y32) -> 47 | AD32: =SUM(AA32:AC32) -> 0 | AE32: 8 | AF32: 8 | AG32: 53 | AH32: =SUM(AE32:AG32) -> 69 | AL32: =SUM(AI32:AK32) -> 0 | AM32: 20 | AN32: 19 | AO32: 48 | AP32: =SUM(AM32:AO32) -> 87 | AT32: =SUM(AQ32:AS32) -> 0 | AX32: =SUM(AU32:AW32) -> 0 | AY32: 20 | AZ32: 20 | BA32: 53 | BB32: =SUM(AY32:BA32) -> 93 | BC32: 10 | BD32: 40 | BE32: 41 | BF32: =SUM(BC32:BE32) -> 91 | BJ32: =SUM(BG32:BI32) -> 0 | BK32: 10 | BL32: 10 | BM32: 38 | BN32: =SUM(Table_6[[#This Row],[CAT59]:[EXAM61]]) -> 58 | BO32: 20 | BP32: 20 | BQ32: 34 | BR32: =SUM(BO32:BQ32) -> 74 | BV32: =SUM(BS32:BU32) -> 0
A33: ='[1]student detail'!A32 -> BDS/22/063 | B33: ='[1]student detail'!B32 -> EKEMEZIE KAMSI | C33: 10 | D33: 5 | E33: 38 | F33: =SUM(Table_6[[#This Row],[CAT]:[EXAM]]) -> 53 | J33: =SUM(Table_6[[#This Row],[CAT3]:[EXAM5]]) -> 0 | K33: 17 | L33: 20 | M33: 30 | N33: =SUM(K33:M33) -> 67 | O33: 10 | P33: 19 | Q33: 33 | R33: =SUM(O33:Q33) -> 62 | S33: 10 | T33: 16 | U33: 40 | V33: =SUM(S33:U33) -> 66 | W33: 10 | X33: 11 | Y33: 23 | Z33: =SUM(W33:Y33) -> 44 | AD33: =SUM(AA33:AC33) -> 0 | AE33: 4 | AF33: 10 | AG33: 40 | AH33: =SUM(AE33:AG33) -> 54 | AL33: =SUM(AI33:AK33) -> 0 | AM33: 20 | AN33: 20 | AO33: 10 | AP33: =SUM(AM33:AO33) -> 50 | AT33: =SUM(AQ33:AS33) -> 0 | AX33: =SUM(AU33:AW33) -> 0 | AY33: 20 | AZ33: 20 | BA33: 53 | BB33: =SUM(AY33:BA33) -> 93 | BC33: 10 | BD33: 40 | BE33: 45 | BF33: =SUM(BC33:BE33) -> 95 | BJ33: =SUM(BG33:BI33) -> 0 | BK33: 10 | BL33: 22 | BM33: 33 | BN33: =SUM(Table_6[[#This Row],[CAT59]:[EXAM61]]) -> 65 | BO33: 20 | BP33: 20 | BQ33: 35 | BR33: =SUM(BO33:BQ33) -> 75 | BV33: =SUM(BS33:BU33) -> 0
A34: ='[1]student detail'!A33 -> BDS/22/064 | B34: ='[1]student detail'!B33 -> AKANDU CHISOM ADA | C34: 10 | D34: 8 | E34: 38 | F34: =SUM(Table_6[[#This Row],[CAT]:[EXAM]]) -> 56 | J34: =SUM(Table_6[[#This Row],[CAT3]:[EXAM5]]) -> 0 | L34: 20 | M34: 14 | N34: =SUM(K34:M34) -> 34 | O34: 17 | P34: 10 | Q34: 21 | R34: =SUM(O34:Q34) -> 48 | S34: 10 | T34: 10 | U34: 20 | V34: =SUM(S34:U34) -> 40 | W34: 10 | X34: 10 | Y34: 17 | Z34: =SUM(W34:Y34) -> 37 | AD34: =SUM(AA34:AC34) -> 0 | AE34: 10 | AF34: 12 | AG34: 40 | AH34: =SUM(AE34:AG34) -> 62 | AL34: =SUM(AI34:AK34) -> 0 | AM34: 20 | AN34: 20 | AO34: 9 | AP34: =SUM(AM34:AO34) -> 49 | AT34: =SUM(AQ34:AS34) -> 0 | AX34: =SUM(AU34:AW34) -> 0 | AY34: 20 | AZ34: 20 | BA34: 44 | BB34: =SUM(AY34:BA34) -> 84 | BC34: 10 | BD34: 27 | BE34: 44 | BF34: =SUM(BC34:BE34) -> 81 | BJ34: =SUM(BG34:BI34) -> 0 | BK34: 10 | BL34: 20 | BM34: 12 | BN34: =SUM(Table_6[[#This Row],[CAT59]:[EXAM61]]) -> 42 | BO34: 20 | BP34: 20 | BQ34: 35 | BR34: =SUM(BO34:BQ34) -> 75 | BV34: =SUM(BS34:BU34) -> 0
A35: ='[1]student detail'!A34 -> BDS/22/065 | B35: ='[1]student detail'!B34 -> AHAMEFULA KING JUDE | C35: 10 | D35: 10 | E35: 52 | F35: =SUM(Table_6[[#This Row],[CAT]:[EXAM]]) -> 72 | J35: =SUM(Table_6[[#This Row],[CAT3]:[EXAM5]]) -> 0 | K35: 12 | L35: 20 | M35: 29 | N35: =SUM(K35:M35) -> 61 | O35: 20 | P35: 2 | Q35: 42 | R35: =SUM(O35:Q35) -> 64 | S35: 10 | T35: 9 | U35: 40 | V35: =SUM(S35:U35) -> 59 | W35: 10 | X35: 10 | Y35: 21 | Z35: =SUM(W35:Y35) -> 41 | AD35: =SUM(AA35:AC35) -> 0 | AE35: 8 | AF35: 10 | AG35: 55 | AH35: =SUM(AE35:AG35) -> 73 | AL35: =SUM(AI35:AK35) -> 0 | AM35: 20 | AN35: 19 | AO35: 45 | AP35: =SUM(AM35:AO35) -> 84 | AT35: =SUM(AQ35:AS35) -> 0 | AX35: =SUM(AU35:AW35) -> 0 | AY35: 20 | AZ35: 20 | BA35: 45 | BB35: =SUM(AY35:BA35) -> 85 | BC35: 10 | BD35: 29 | BE35: 45 | BF35: =SUM(BC35:BE35) -> 84 | BJ35: =SUM(BG35:BI35) -> 0 | BK35: 10 | BL35: 20 | BM35: 35 | BN35: =SUM(Table_6[[#This Row],[CAT59]:[EXAM61]]) -> 65 | BO35: 20 | BP35: 20 | BQ35: 43 | BR35: =SUM(BO35:BQ35) -> 83 | BV35: =SUM(BS35:BU35) -> 0
A36: ='[1]student detail'!A35 -> BDS/22/066 | B36: ='[1]student detail'!B35 -> ANOCHIE BLESSING | C36: 15 | D36: 12 | E36: 52 | F36: =SUM(Table_6[[#This Row],[CAT]:[EXAM]]) -> 79 | J36: =SUM(Table_6[[#This Row],[CAT3]:[EXAM5]]) -> 0 | K36: 20 | L36: 20 | M36: 41 | N36: =SUM(K36:M36) -> 81 | O36: 11 | P36: 10 | Q36: 24 | R36: =SUM(O36:Q36) -> 45 | S36: 10 | T36: 15 | U36: 36 | V36: =SUM(S36:U36) -> 61 | W36: 14 | X36: 10 | Y36: 23 | Z36: =SUM(W36:Y36) -> 47 | AD36: =SUM(AA36:AC36) -> 0 | AE36: 14 | AF36: 10 | AG36: 54 | AH36: =SUM(AE36:AG36) -> 78 | AL36: =SUM(AI36:AK36) -> 0 | AM36: 20 | AN36: 19 | AO36: 54 | AP36: =SUM(AM36:AO36) -> 93 | AT36: =SUM(AQ36:AS36) -> 0 | AX36: =SUM(AU36:AW36) -> 0 | AY36: 20 | AZ36: 20 | BA36: 53 | BB36: =SUM(AY36:BA36) -> 93 | BC36: 10 | BD36: 40 | BE36: 41 | BF36: =SUM(BC36:BE36) -> 91 | BJ36: 0 | BK36: 10 | BL36: 20 | BM36: 33 | BN36: =SUM(Table_6[[#This Row],[CAT59]:[EXAM61]]) -> 63 | BO36: 20 | BP36: 20 | BQ36: 35 | BR36: =SUM(BO36:BQ36) -> 75 | BV36: =SUM(BS36:BU36) -> 0
A37: ='[1]student detail'!A36 -> BDS/22/067 | B37: ='[1]student detail'!B36 -> CHIGOZIRIM ANNOINTING | C37: 10 | D37: 12 | E37: 38 | F37: =SUM(Table_6[[#This Row],[CAT]:[EXAM]]) -> 60 | J37: =SUM(Table_6[[#This Row],[CAT3]:[EXAM5]]) -> 0 | K37: 17 | L37: 20 | M37: 33 | N37: =SUM(K37:M37) -> 70 | O37: 10 | P37: 16 | Q37: 38 | R37: =SUM(O37:Q37) -> 64 | S37: 10 | T37: 16 | U37: 30 | V37: =SUM(S37:U37) -> 56 | W37: 7 | X37: 10 | Y37: 16 | Z37: =SUM(W37:Y37) -> 33 | AD37: =SUM(AA37:AC37) -> 0 | AE37: 8 | AF37: 10 | AG37: 40 | AH37: =SUM(AE37:AG37) -> 58 | AL37: =SUM(AI37:AK37) -> 0 | AM37: 20 | AN37: 20 | AO37: 24 | AP37: =SUM(AM37:AO37) -> 64 | AT37: =SUM(AQ37:AS37) -> 0 | AX37: =SUM(AU37:AW37) -> 0 | AY37: 20 | AZ37: 20 | BA37: 49 | BB37: =SUM(AY37:BA37) -> 89 | BC37: 10 | BD37: 40 | BE37: 44 | BF37: =SUM(BC37:BE37) -> 94 | BJ37: =SUM(BG37:BI37) -> 0 | BK37: 10 | BL37: 20 | BM37: 36 | BN37: =SUM(Table_6[[#This Row],[CAT59]:[EXAM61]]) -> 66 | BO37: 20 | BP37: 20 | BQ37: 30 | BR37: =SUM(BO37:BQ37) -> 70 | BV37: =SUM(BS37:BU37) -> 0
A38: ='[1]student detail'!A37 -> BDS/22/068 | B38: ='[1]student detail'!B37 -> EZI DIVINE | C38: 10 | D38: 8 | E38: 54 | F38: =SUM(Table_6[[#This Row],[CAT]:[EXAM]]) -> 72 | J38: =SUM(Table_6[[#This Row],[CAT3]:[EXAM5]]) -> 0 | K38: 20 | L38: 20 | M38: 30 | N38: =SUM(K38:M38) -> 70 | O38: 12 | P38: 10 | Q38: 24 | R38: =SUM(O38:Q38) -> 46 | S38: 10 | T38: 15 | U38: 20 | V38: =SUM(S38:U38) -> 45 | W38: 19 | X38: 10 | Y38: 21 | Z38: =SUM(W38:Y38) -> 50 | AD38: =SUM(AA38:AC38) -> 0 | AE38: 10 | AF38: 12 | AG38: 50 | AH38: =SUM(AE38:AG38) -> 72 | AL38: =SUM(AI38:AK38) -> 0 | AM38: 20 | AN38: 19 | AO38: 33 | AP38: =SUM(AM38:AO38) -> 72 | AT38: =SUM(AQ38:AS38) -> 0 | AX38: =SUM(AU38:AW38) -> 0 | AY38: 20 | AZ38: 20 | BA38: 40 | BB38: =SUM(AY38:BA38) -> 80 | BC38: 10 | BD38: 40 | BE38: 47 | BF38: =SUM(BC38:BE38) -> 97 | BJ38: =SUM(BG38:BI38) -> 0 | BK38: 10 | BL38: 10 | BM38: 32 | BN38: =SUM(Table_6[[#This Row],[CAT59]:[EXAM61]]) -> 52 | BO38: 20 | BP38: 20 | BQ38: 37 | BR38: =SUM(BO38:BQ38) -> 77 | BV38: =SUM(BS38:BU38) -> 0
A39: ='[1]student detail'!A38 -> BDS/22/069 | B39: ='[1]student detail'!B38 -> EZUMA FAVOUR | F39: =SUM(Table_6[[#This Row],[CAT]:[EXAM]]) -> 0 | J39: =SUM(Table_6[[#This Row],[CAT3]:[EXAM5]]) -> 0 | K39: 15 | L39: 20 | N39: =SUM(K39:M39) -> 35 | R39: =SUM(O39:Q39) -> 0 | S39: 10 | T39: 15 | V39: =SUM(S39:U39) -> 25 | Z39: =SUM(W39:Y39) -> 0 | AD39: =SUM(AA39:AC39) -> 0 | AH39: =SUM(AE39:AG39) -> 0 | AL39: =SUM(AI39:AK39) -> 0 | AP39: =SUM(AM39:AO39) -> 0 | AT39: =SUM(AQ39:AS39) -> 0 | AX39: =SUM(AU39:AW39) -> 0 | BB39: =SUM(AY39:BA39) -> 0 | BC39: 10 | BD39: 18 | BE39: 44 | BF39: =SUM(BC39:BE39) -> 72 | BJ39: =SUM(BG39:BI39) -> 0 | BN39: =SUM(Table_6[[#This Row],[CAT59]:[EXAM61]]) -> 0 | BR39: =SUM(BO39:BQ39) -> 0 | BV39: =SUM(BS39:BU39) -> 0
A40: ='[1]student detail'!A39 -> BDS/22/070 | B40: ='[1]student detail'!B39 -> GABRIEL MUNACHIMSO | C40: 10 | D40: 8 | E40: 48 | F40: =SUM(Table_6[[#This Row],[CAT]:[EXAM]]) -> 66 | J40: =SUM(Table_6[[#This Row],[CAT3]:[EXAM5]]) -> 0 | K40: 14 | L40: 10 | M40: 35 | N40: =SUM(K40:M40) -> 59 | O40: 10 | P40: 13 | Q40: 12 | S40: 10 | T40: 11 | U40: 30 | V40: =SUM(S40:U40) -> 51 | W40: 11 | X40: 11 | Y40: 18 | Z40: =SUM(W40:Y40) -> 40 | AD40: =SUM(AA40:AC40) -> 0 | AE40: 10 | AF40: 15 | AG40: 50 | AH40: =SUM(AE40:AG40) -> 75 | AL40: =SUM(AI40:AK40) -> 0 | AM40: 20 | AN40: 18 | AO40: 32 | AP40: =SUM(AM40:AO40) -> 70 | AT40: =SUM(AQ40:AS40) -> 0 | AX40: =SUM(AU40:AW40) -> 0 | AY40: 20 | AZ40: 20 | BA40: 28 | BB40: =SUM(AY40:BA40) -> 68 | BC40: 10 | BD40: 39 | BE40: 46 | BF40: =SUM(BC40:BE40) -> 95 | BJ40: =SUM(BG40:BI40) -> 0 | BK40: 10 | BL40: 20 | BM40: 15 | BN40: =SUM(Table_6[[#This Row],[CAT59]:[EXAM61]]) -> 45 | BO40: 20 | BP40: 20 | BQ40: 32 | BR40: =SUM(BO40:BQ40) -> 72 | BV40: =SUM(BS40:BU40) -> 0
...
